Traceback (most recent call last):
  File "/usr/local/lib/python3.10/dist-packages/jupyter_cache/executors/utils.py", line 58, in single_nb_execution
    executenb(
  File "/usr/local/lib/python3.10/dist-packages/nbclient/client.py", line 1305, in execute
    return NotebookClient(nb=nb, resources=resources, km=km, **kwargs).execute()
  File "/usr/local/lib/python3.10/dist-packages/jupyter_core/utils/__init__.py", line 166, in wrapped
    return loop.run_until_complete(inner)
  File "/usr/lib/python3.10/asyncio/base_events.py", line 649, in run_until_complete
    return future.result()
  File "/usr/local/lib/python3.10/dist-packages/nbclient/client.py", line 705, in async_execute
    await self.async_execute_cell(
  File "/usr/local/lib/python3.10/dist-packages/nbclient/client.py", line 1058, in async_execute_cell
    await self._check_raise_for_error(cell, cell_index, exec_reply)
  File "/usr/local/lib/python3.10/dist-packages/nbclient/client.py", line 914, in _check_raise_for_error
    raise CellExecutionError.from_cell_and_msg(cell, exec_reply_content)
nbclient.exceptions.CellExecutionError: An error occurred while executing the following cell:
------------------
train_data = tfidf.fit_transform(documents_list)
------------------


[0;31m[0m
[0;31mValueError[0mTraceback (most recent call last)
[0;32m<ipython-input-20-78b957183ddf>[0m in [0;36m<cell line: 1>[0;34m()[0m
[0;32m----> 1[0;31m [0mtrain_data[0m [0;34m=[0m [0mtfidf[0m[0;34m.[0m[0mfit_transform[0m[0;34m([0m[0mdocuments_list[0m[0;34m)[0m[0;34m[0m[0;34m[0m[0m
[0m
[0;32m/usr/local/lib/python3.10/dist-packages/sklearn/feature_extraction/text.py[0m in [0;36mfit_transform[0;34m(self, raw_documents, y)[0m
[1;32m   2131[0m             [0msublinear_tf[0m[0;34m=[0m[0mself[0m[0;34m.[0m[0msublinear_tf[0m[0;34m,[0m[0;34m[0m[0;34m[0m[0m
[1;32m   2132[0m         )
[0;32m-> 2133[0;31m         [0mX[0m [0;34m=[0m [0msuper[0m[0;34m([0m[0;34m)[0m[0;34m.[0m[0mfit_transform[0m[0;34m([0m[0mraw_documents[0m[0;34m)[0m[0;34m[0m[0;34m[0m[0m
[0m[1;32m   2134[0m         [0mself[0m[0;34m.[0m[0m_tfidf[0m[0;34m.[0m[0mfit[0m[0;34m([0m[0mX[0m[0;34m)[0m[0;34m[0m[0;34m[0m[0m
[1;32m   2135[0m         [0;31m# X is already a transformed view of raw_documents so[0m[0;34m[0m[0;34m[0m[0m

[0;32m/usr/local/lib/python3.10/dist-packages/sklearn/feature_extraction/text.py[0m in [0;36mfit_transform[0;34m(self, raw_documents, y)[0m
[1;32m   1386[0m                     [0;32mbreak[0m[0;34m[0m[0;34m[0m[0m
[1;32m   1387[0m [0;34m[0m[0m
[0;32m-> 1388[0;31m         [0mvocabulary[0m[0;34m,[0m [0mX[0m [0;34m=[0m [0mself[0m[0;34m.[0m[0m_count_vocab[0m[0;34m([0m[0mraw_documents[0m[0;34m,[0m [0mself[0m[0;34m.[0m[0mfixed_vocabulary_[0m[0;34m)[0m[0;34m[0m[0;34m[0m[0m
[0m[1;32m   1389[0m [0;34m[0m[0m
[1;32m   1390[0m         [0;32mif[0m [0mself[0m[0;34m.[0m[0mbinary[0m[0;34m:[0m[0;34m[0m[0;34m[0m[0m

[0;32m/usr/local/lib/python3.10/dist-packages/sklearn/feature_extraction/text.py[0m in [0;36m_count_vocab[0;34m(self, raw_documents, fixed_vocab)[0m
[1;32m   1292[0m             [0mvocabulary[0m [0;34m=[0m [0mdict[0m[0;34m([0m[0mvocabulary[0m[0;34m)[0m[0;34m[0m[0;34m[0m[0m
[1;32m   1293[0m             [0;32mif[0m [0;32mnot[0m [0mvocabulary[0m[0;34m:[0m[0;34m[0m[0;34m[0m[0m
[0;32m-> 1294[0;31m                 raise ValueError(
[0m[1;32m   1295[0m                     [0;34m"empty vocabulary; perhaps the documents only contain stop words"[0m[0;34m[0m[0;34m[0m[0m
[1;32m   1296[0m                 )

[0;31mValueError[0m: empty vocabulary; perhaps the documents only contain stop words

